<?xml version="1.0"?>
<robot xmlns:xacro="http://www.ros.org/wiki/xacro">


    <material name="white">
        <color rgba="1 1 1 1"/>
    </material>

    <material name="orange">
        <color rgba="1 0 .3 0.1 1"/>
    </material>

    <material name="blue">
        <color rgba="0.2 0.2 1 1"/>
    </material>

    <material name="black">
        <color rgba="0 0 0 1"/>
    </material>

<!-- BASE LINK -->

    <link name="base_link"> <!--this is traditionally the first link in a robot structure -->

    </link>

<!-- CHASSIS LINK -->

    <joint name="chassis_joint" type="fixed"> <!--this is the joint that will include the basic chassis dimensions in XYZ -->
        <parent link="base_link"/> <!--this references the first link we created for our robot and uses it as a dependency -->
        <child link="chassis"/>
        <origin xyz="-0.1 0 0"/> <!--this is the origin of this link.  values are in meters.  origin is moved back from the base link by .1 meters in X and has no change in Y or Z -->
    </joint>

    <link name="chassis">
        <visual>
            <origin xyz="0.15 0 .075"/> <!--the box we defined below has its origin at the center of the box.  This shifts the box up and forward by half the length of these two sides so it is visually located where we want it in reference to the robot. -->
            <geometry>
                <box size="0.3 0.3 0.15"/> <!--this defines what shape (box in this case) the chassis will be and also defines the size of the box (values are in meters) -->
            </geometry>
            <material name="white"/>
        </visual>
         <collision>
            <origin xyz="0.15 0 .075"/> <!--the box we defined below has its origin at the center of the box.  This shifts the box up and forward by half the length of these two sides so it is visually located where we want it in reference to the robot. -->
            <geometry>
                <box size="0.3 0.3 0.15"/> <!--this defines what shape (box in this case) the chassis will be and also defines the size of the box (values are in meters) -->
            </geometry>
        </collision>
    </link>

<!-- LEFT WHEEL LINK -->

<joint name="left_wheel_joint" type="continuous">
    <parent link="base_link"/>
    <child link="left_wheel"/>
    <origin xyz="0 0.175 0" rpy="-${pi/2} 0 0"/>
    <axis xyz="0 0 1"/>
</joint>

<link name="left_wheel">
    <visual>
        <geometry>
            <cylinder radius="0.05" length="0.04"/>
        </geometry>
        <material name="blue"/>
    </visual>
    <collision>
        <geometry>
            <cylinder radius="0.05" length="0.04"/>
        </geometry>
    </collision>
</link>

<!-- RIGHT WHEEL LINK -->

<joint name="right_wheel_joint" type="continuous">
    <parent link="base_link"/>
    <child link="right_wheel"/>
    <origin xyz="0 -0.175 0" rpy="${pi/2} 0 0"/>
    <axis xyz="0 0 -1"/>
</joint>

<link name="right_wheel">
    <visual>
        <geometry>
            <cylinder radius="0.05" length="0.04"/>
        </geometry>
        <material name="blue"/>
    </visual>
    <collision>
        <geometry>
            <cylinder radius="0.05" length="0.04"/>
        </geometry>
    </collision>
</link>

<!-- CASTER WHEEL LINK -->

<joint name="caster_wheel_joint" type="fixed">
    <parent link="chassis"/>
    <child link="caster_wheel"/>
    <origin xyz="0.24 0 0"/>
</joint>

<link name="caster_wheel">
    <visual>
        <geometry>
            <sphere radius="0.05"/>
        </geometry>
        <material name="black"/>
    </visual>
    <collision>
        <geometry>
            <sphere radius="0.05"/>
        </geometry>
        <material name="black"/>
    </collision>
</link>


</robot>